<!DOCTYPE html>
<html lang="en">
<head>
	<meta charset="UTF-8">
	<title>Document</title>
</head>
<body>
	<script type="text/javascript" src="./jquery.min.js"></script>
	<script type="text/javascript">
		// 定义第一个Promise
		function sendAjax1() {
			// 返回一个Promise
			return new Promise((resolve, reject) => {
				// 发送ajax
				$.ajax({
					url: "/a",
					data: "",
					type: "get",
					dataType: "json",
					success: (data) => {
						// 传递四个参数
						// reject("第一个错误");
						resolve();
					}
				});
			});
		} 
		// 定义第二个Promise
		function sendAjax2(data) {
			// 返回一个Promise
			return new Promise((resolve, reject) => {
				// 发送ajax
				$.ajax({
					url: "/b",
					data: data,
					type: "get",
					dataType: "json",
					success: (data) => {
						// resolve(data);
						reject("第二个错误")
					}
				});
			});
		}
		
		// 执行第一个Promise
		var p = sendAjax1();
		p.then(() => {
			return sendAjax2();
		})
		.then(() => {
			
		})
		// .catch表示捕获 当之前的代码中Promsie的状态变为rejected 或者出现异常时 会调用catch捕获内部的错误
		.catch((msg) => {
			console.log(msg)
		})

	</script>
</body>
</html>